## ComfyUI-Manager: installing dependencies done.
[2024-09-13 18:12] ** ComfyUI startup time: 2024-09-13 18:12:22.075251
[2024-09-13 18:12] ** Platform: Windows
[2024-09-13 18:12] ** Python version: 3.11.6 | packaged by conda-forge | (main, Oct  3 2023, 10:29:11) [MSC v.1935 64 bit (AMD64)]
[2024-09-13 18:12] ** Python executable: D:\comfyui\.ext\python.exe
[2024-09-13 18:12] ** ComfyUI Path: D:\comfyui
[2024-09-13 18:12] ** Log path: D:\comfyui\comfyui.log
[2024-09-13 18:12] 
Prestartup times for custom nodes:
[2024-09-13 18:12]    0.0 seconds: D:\comfyui\custom_nodes\rgthree-comfy
[2024-09-13 18:12]    3.6 seconds: D:\comfyui\custom_nodes\ComfyUI-Manager
[2024-09-13 18:12] 
Total VRAM 8192 MB, total RAM 16215 MB
[2024-09-13 18:12] pytorch version: 2.3.1+cu121
[2024-09-13 18:12] xformers version: 0.0.27
[2024-09-13 18:12] Set vram state to: NORMAL_VRAM
[2024-09-13 18:12] Device: cuda:0 NVIDIA GeForce RTX 2060 SUPER : native
[2024-09-13 18:12] Using xformers cross attention
[2024-09-13 18:12] [Prompt Server] web root: D:\comfyui\web
[2024-09-13 18:12] Adding extra search path checkpoints D:\sd-webui-aki-v4.8\models/Stable-diffusion
[2024-09-13 18:12] Adding extra search path configs D:\sd-webui-aki-v4.8\models/Stable-diffusion
[2024-09-13 18:12] Adding extra search path vae D:\sd-webui-aki-v4.8\models/VAE
[2024-09-13 18:12] Adding extra search path loras D:\sd-webui-aki-v4.8\models/Lora
[2024-09-13 18:12] Adding extra search path loras D:\sd-webui-aki-v4.8\models/LyCORIS
[2024-09-13 18:12] Adding extra search path upscale_models D:\sd-webui-aki-v4.8\models/ESRGAN
[2024-09-13 18:12] Adding extra search path upscale_models D:\sd-webui-aki-v4.8\models/RealESRGAN
[2024-09-13 18:12] Adding extra search path upscale_models D:\sd-webui-aki-v4.8\models/SwinIR
[2024-09-13 18:12] Adding extra search path embeddings D:\sd-webui-aki-v4.8\embeddings
[2024-09-13 18:12] Adding extra search path hypernetworks D:\sd-webui-aki-v4.8\models/hypernetworks
[2024-09-13 18:12] Adding extra search path controlnet D:\sd-webui-aki-v4.8\models/ControlNet
[2024-09-13 18:12] [AnimateDiffEvo] - [0;31mERROR[0m - No motion models found. Please download one and place in: ['D:\\comfyui\\custom_nodes\\ComfyUI-AnimateDiff-Evolved\\models', 'D:\\comfyui\\models\\animatediff_models']
[2024-09-13 18:12] ### Loading: ComfyUI-Impact-Pack (V7.5)
[2024-09-13 18:12] ### Loading: ComfyUI-Impact-Pack (Subpack: V0.6)
[2024-09-13 18:12] [Impact Pack] Wildcards loading done.
[2024-09-13 18:12] ### Loading: ComfyUI-Inspire-Pack (V1.2)
[2024-09-13 18:12] Total VRAM 8192 MB, total RAM 16215 MB
[2024-09-13 18:12] pytorch version: 2.3.1+cu121
[2024-09-13 18:12] xformers version: 0.0.27
[2024-09-13 18:12] Set vram state to: NORMAL_VRAM
[2024-09-13 18:12] Device: cuda:0 NVIDIA GeForce RTX 2060 SUPER : native
[2024-09-13 18:12] ### Loading: ComfyUI-Manager (V2.50.3)
[2024-09-13 18:12] ### ComfyUI Revision: 2683 [b962db99] | Released on '2024-09-12'
[2024-09-13 18:12] Exception in thread Thread-8 (<lambda>):
[2024-09-13 18:12] Traceback (most recent call last):
[2024-09-13 18:12]   File "D:\comfyui\.ext\Lib\site-packages\aiohttp\connector.py", line 1301, in _create_direct_connection
[2024-09-13 18:12]     hosts = await self._resolve_host(host, port, traces=traces)
[2024-09-13 18:12]             ^^^^^^^^^^^^^^^^^^^^^^^^^^^^^^^^^^^^^^^^^^^^^^^^^^^
[2024-09-13 18:12]   File "D:\comfyui\.ext\Lib\site-packages\aiohttp\connector.py", line 911, in _resolve_host
[2024-09-13 18:12]     return await asyncio.shield(resolved_host_task)
[2024-09-13 18:12]            ^^^^^^^^^^^^^^^^^^^^^^^^^^^^^^^^^^^^^^^^
[2024-09-13 18:12]   File "D:\comfyui\.ext\Lib\site-packages\aiohttp\connector.py", line 948, in _resolve_host_with_throttle
[2024-09-13 18:12]     addrs = await self._resolver.resolve(host, port, family=self._family)
[2024-09-13 18:12]             ^^^^^^^^^^^^^^^^^^^^^^^^^^^^^^^^^^^^^^^^^^^^^^^^^^^^^^^^^^^^^
[2024-09-13 18:12]   File "D:\comfyui\.ext\Lib\site-packages\aiohttp\resolver.py", line 37, in resolve
[2024-09-13 18:12]     infos = await self._loop.getaddrinfo(
[2024-09-13 18:12]             ^^^^^^^^^^^^^^^^^^^^^^^^^^^^^
[2024-09-13 18:12]   File "D:\comfyui\.ext\Lib\asyncio\base_events.py", line 867, in getaddrinfo
[2024-09-13 18:12]     return await self.run_in_executor(
[2024-09-13 18:12]            ^^^^^^^^^^^^^^^^^^^^^^^^^^^
[2024-09-13 18:12]   File "D:\comfyui\.ext\Lib\concurrent\futures\thread.py", line 58, in run
[2024-09-13 18:12]     result = self.fn(*self.args, **self.kwargs)
[2024-09-13 18:12]              ^^^^^^^^^^^^^^^^^^^^^^^^^^^^^^^^^^
[2024-09-13 18:12]   File "D:\comfyui\.ext\Lib\socket.py", line 962, in getaddrinfo
[2024-09-13 18:12]     for res in _socket.getaddrinfo(host, port, family, type, proto, flags):
[2024-09-13 18:12]                ^^^^^^^^^^^^^^^^^^^^^^^^^^^^^^^^^^^^^^^^^^^^^^^^^^^^^^^^^^^
[2024-09-13 18:12] socket.gaierror: [Errno 11004] getaddrinfo failed
[2024-09-13 18:12] 
[2024-09-13 18:12] The above exception was the direct cause of the following exception:
[2024-09-13 18:12] 
[2024-09-13 18:12] Traceback (most recent call last):
[2024-09-13 18:12]   File "D:\comfyui\.ext\Lib\threading.py", line 1045, in _bootstrap_inner
[2024-09-13 18:12]     self.run()
[2024-09-13 18:12]   File "<enhanced_experience vendors.sentry_sdk.integrations.threading>", line 99, in run
[2024-09-13 18:12]   File "<enhanced_experience vendors.sentry_sdk.integrations.threading>", line 94, in _run_old_run_func
[2024-09-13 18:12]   File "<enhanced_experience vendors.sentry_sdk.utils>", line 1649, in reraise
[2024-09-13 18:12]   File "<enhanced_experience vendors.sentry_sdk.integrations.threading>", line 92, in _run_old_run_func
[2024-09-13 18:12]   File "D:\comfyui\.ext\Lib\threading.py", line 982, in run
[2024-09-13 18:12]     self._target(*self._args, **self._kwargs)
[2024-09-13 18:12]   File "D:\comfyui\custom_nodes\ComfyUI-Manager\glob\manager_server.py", line 1343, in <lambda>
[2024-09-13 18:12]     threading.Thread(target=lambda: asyncio.run(default_cache_update())).start()
[2024-09-13 18:12]                                     ^^^^^^^^^^^^^^^^^^^^^^^^^^^^^^^^^^^
[2024-09-13 18:12]   File "D:\comfyui\.ext\Lib\asyncio\runners.py", line 190, in run
[2024-09-13 18:12]     return runner.run(main)
[2024-09-13 18:12]            ^^^^^^^^^^^^^^^^
[2024-09-13 18:12]   File "D:\comfyui\.ext\Lib\asyncio\runners.py", line 118, in run
[2024-09-13 18:12]     return self._loop.run_until_complete(task)
[2024-09-13 18:12]            ^^^^^^^^^^^^^^^^^^^^^^^^^^^^^^^^^^^
[2024-09-13 18:12]   File "D:\comfyui\.ext\Lib\asyncio\base_events.py", line 653, in run_until_complete
[2024-09-13 18:12]     return future.result()
[2024-09-13 18:12]            ^^^^^^^^^^^^^^^
[2024-09-13 18:12]   File "D:\comfyui\custom_nodes\ComfyUI-Manager\glob\manager_server.py", line 1340, in default_cache_update
[2024-09-13 18:12]     await asyncio.gather(a, b, c, d, e)
[2024-09-13 18:12]   File "D:\comfyui\custom_nodes\ComfyUI-Manager\glob\manager_server.py", line 1327, in get_cache
[2024-09-13 18:12]     json_obj = await core.get_data(uri, True)
[2024-09-13 18:12]                ^^^^^^^^^^^^^^^^^^^^^^^^^^^^^^
[2024-09-13 18:12]   File "D:\comfyui\custom_nodes\ComfyUI-Manager\glob\manager_core.py", line 620, in get_data
[2024-09-13 18:12]     async with session.get(uri) as resp:
[2024-09-13 18:12]   File "D:\comfyui\.ext\Lib\site-packages\aiohttp\client.py", line 1353, in __aenter__
[2024-09-13 18:12]     self._resp = await self._coro
[2024-09-13 18:12]                  ^^^^^^^^^^^^^^^^
[2024-09-13 18:12]   File "D:\comfyui\.ext\Lib\site-packages\aiohttp\client.py", line 657, in _request
[2024-09-13 18:12]     conn = await self._connector.connect(
[2024-09-13 18:12]            ^^^^^^^^^^^^^^^^^^^^^^^^^^^^^^
[2024-09-13 18:12]   File "D:\comfyui\.ext\Lib\site-packages\aiohttp\connector.py", line 564, in connect
[2024-09-13 18:12]     proto = await self._create_connection(req, traces, timeout)
[2024-09-13 18:12]             ^^^^^^^^^^^^^^^^^^^^^^^^^^^^^^^^^^^^^^^^^^^^^^^^^^^
[2024-09-13 18:12]   File "D:\comfyui\.ext\Lib\site-packages\aiohttp\connector.py", line 975, in _create_connection
[2024-09-13 18:12]     _, proto = await self._create_direct_connection(req, traces, timeout)
[2024-09-13 18:12]                ^^^^^^^^^^^^^^^^^^^^^^^^^^^^^^^^^^^^^^^^^^^^^^^^^^^^^^^^^^
[2024-09-13 18:12]   File "D:\comfyui\.ext\Lib\site-packages\aiohttp\connector.py", line 1307, in _create_direct_connection
[2024-09-13 18:12]     raise ClientConnectorError(req.connection_key, exc) from exc
[2024-09-13 18:12] aiohttp.client_exceptions.ClientConnectorError: Cannot connect to host raw.githubusercontent.com:443 ssl:default [getaddrinfo failed]
[2024-09-13 18:13] Traceback (most recent call last):
  File "D:\comfyui\.ext\Lib\site-packages\urllib3\connection.py", line 174, in _new_conn
    conn = connection.create_connection(
           ^^^^^^^^^^^^^^^^^^^^^^^^^^^^^
  File "D:\comfyui\.ext\Lib\site-packages\urllib3\util\connection.py", line 95, in create_connection
    raise err
  File "D:\comfyui\.ext\Lib\site-packages\urllib3\util\connection.py", line 85, in create_connection
    sock.connect(sa)
TimeoutError: [WinError 10060] Áî±‰∫éËøûÊé•ÊñπÂú®‰∏ÄÊÆµÊó∂Èó¥ÂêéÊ≤°ÊúâÊ≠£Á°ÆÁ≠îÂ§çÊàñËøûÊé•ÁöÑ‰∏ªÊú∫Ê≤°ÊúâÂèçÂ∫îÔºåËøûÊé•Â∞ùËØïÂ§±Ë¥•„ÄÇ

During handling of the above exception, another exception occurred:

Traceback (most recent call last):
  File "D:\comfyui\.ext\Lib\site-packages\urllib3\connectionpool.py", line 716, in urlopen
    httplib_response = self._make_request(
                       ^^^^^^^^^^^^^^^^^^^
  File "D:\comfyui\.ext\Lib\site-packages\urllib3\connectionpool.py", line 404, in _make_request
    self._validate_conn(conn)
  File "D:\comfyui\.ext\Lib\site-packages\urllib3\connectionpool.py", line 1061, in _validate_conn
    conn.connect()
  File "D:\comfyui\.ext\Lib\site-packages\urllib3\connection.py", line 363, in connect
    self.sock = conn = self._new_conn()
                       ^^^^^^^^^^^^^^^^
  File "D:\comfyui\.ext\Lib\site-packages\urllib3\connection.py", line 179, in _new_conn
    raise ConnectTimeoutError(
urllib3.exceptions.ConnectTimeoutError: (<urllib3.connection.HTTPSConnection object at 0x000002286EDC3A10>, 'Connection to huggingface.co timed out. (connect timeout=None)')

During handling of the above exception, another exception occurred:

Traceback (most recent call last):
  File "D:\comfyui\.ext\Lib\site-packages\requests\adapters.py", line 667, in send
    resp = conn.urlopen(
           ^^^^^^^^^^^^^
  File "D:\comfyui\.ext\Lib\site-packages\urllib3\connectionpool.py", line 802, in urlopen
    retries = retries.increment(
              ^^^^^^^^^^^^^^^^^^
  File "D:\comfyui\.ext\Lib\site-packages\urllib3\util\retry.py", line 594, in increment
    raise MaxRetryError(_pool, url, error or ResponseError(cause))
urllib3.exceptions.MaxRetryError: HTTPSConnectionPool(host='huggingface.co', port=443): Max retries exceeded with url: /api/models/yzd-v/DWPose/revision/main (Caused by ConnectTimeoutError(<urllib3.connection.HTTPSConnection object at 0x000002286EDC3A10>, 'Connection to huggingface.co timed out. (connect timeout=None)'))

During handling of the above exception, another exception occurred:

Traceback (most recent call last):
  File "D:\comfyui\.ext\Lib\site-packages\huggingface_hub\_snapshot_download.py", line 169, in snapshot_download
    repo_info = api.repo_info(repo_id=repo_id, repo_type=repo_type, revision=revision, token=token)
                ^^^^^^^^^^^^^^^^^^^^^^^^^^^^^^^^^^^^^^^^^^^^^^^^^^^^^^^^^^^^^^^^^^^^^^^^^^^^^^^^^^^
  File "D:\comfyui\.ext\Lib\site-packages\huggingface_hub\utils\_validators.py", line 114, in _inner_fn
    return fn(*args, **kwargs)
           ^^^^^^^^^^^^^^^^^^^
  File "D:\comfyui\.ext\Lib\site-packages\huggingface_hub\hf_api.py", line 2588, in repo_info
    return method(
           ^^^^^^^
  File "D:\comfyui\.ext\Lib\site-packages\huggingface_hub\utils\_validators.py", line 114, in _inner_fn
    return fn(*args, **kwargs)
           ^^^^^^^^^^^^^^^^^^^
  File "D:\comfyui\.ext\Lib\site-packages\huggingface_hub\hf_api.py", line 2372, in model_info
    r = get_session().get(path, headers=headers, timeout=timeout, params=params)
        ^^^^^^^^^^^^^^^^^^^^^^^^^^^^^^^^^^^^^^^^^^^^^^^^^^^^^^^^^^^^^^^^^^^^^^^^
  File "D:\comfyui\.ext\Lib\site-packages\requests\sessions.py", line 602, in get
    return self.request("GET", url, **kwargs)
           ^^^^^^^^^^^^^^^^^^^^^^^^^^^^^^^^^^
  File "D:\comfyui\.ext\Lib\site-packages\requests\sessions.py", line 589, in request
    resp = self.send(prep, **send_kwargs)
           ^^^^^^^^^^^^^^^^^^^^^^^^^^^^^^
  File "D:\comfyui\.ext\Lib\site-packages\requests\sessions.py", line 703, in send
    r = adapter.send(request, **kwargs)
        ^^^^^^^^^^^^^^^^^^^^^^^^^^^^^^^
  File "D:\comfyui\.ext\Lib\site-packages\huggingface_hub\utils\_http.py", line 66, in send
    return super().send(request, *args, **kwargs)
           ^^^^^^^^^^^^^^^^^^^^^^^^^^^^^^^^^^^^^^
  File "D:\comfyui\.ext\Lib\site-packages\requests\adapters.py", line 688, in send
    raise ConnectTimeout(e, request=request)
requests.exceptions.ConnectTimeout: (MaxRetryError("HTTPSConnectionPool(host='huggingface.co', port=443): Max retries exceeded with url: /api/models/yzd-v/DWPose/revision/main (Caused by ConnectTimeoutError(<urllib3.connection.HTTPSConnection object at 0x000002286EDC3A10>, 'Connection to huggingface.co timed out. (connect timeout=None)'))"), '(Request ID: b7ce1afe-d251-4098-a4b7-50baa7d52fa8)')

The above exception was the direct cause of the following exception:

Traceback (most recent call last):
  File "D:\comfyui\nodes.py", line 1993, in load_custom_node
    module_spec.loader.exec_module(module)
  File "<frozen importlib._bootstrap_external>", line 940, in exec_module
  File "<frozen importlib._bootstrap>", line 241, in _call_with_frames_removed
  File "D:\comfyui\custom_nodes\ComfyUI-MimicMotion\__init__.py", line 4, in <module>
    from .nodes import MimicMotionNode, LoadVideo, PreViewVideo
  File "D:\comfyui\custom_nodes\ComfyUI-MimicMotion\nodes.py", line 33, in <module>
    snapshot_download(repo_id="yzd-v/DWPose",local_dir=os.environ["dwpose"],
  File "D:\comfyui\.ext\Lib\site-packages\huggingface_hub\utils\_validators.py", line 114, in _inner_fn
    return fn(*args, **kwargs)
           ^^^^^^^^^^^^^^^^^^^
  File "D:\comfyui\.ext\Lib\site-packages\huggingface_hub\_snapshot_download.py", line 241, in snapshot_download
    raise LocalEntryNotFoundError(
huggingface_hub.utils._errors.LocalEntryNotFoundError: An error happened while trying to locate the files on the Hub and we cannot find the appropriate snapshot folder for the specified revision on the local disk. Please check your internet connection and try again.

[2024-09-13 18:13] Cannot import D:\comfyui\custom_nodes\ComfyUI-MimicMotion module for custom nodes: An error happened while trying to locate the files on the Hub and we cannot find the appropriate snapshot folder for the specified revision on the local disk. Please check your internet connection and try again.
[2024-09-13 18:13] Workspace manager - Openning file hash dict
[2024-09-13 18:13] ü¶Ñü¶ÑLoading: Workspace Manager (V2.1.0)
[2024-09-13 18:13] [36;20m[comfyui_controlnet_aux] | INFO -> Using ckpts path: D:\comfyui\custom_nodes\comfyui_controlnet_aux\ckpts[0m
[2024-09-13 18:13] [36;20m[comfyui_controlnet_aux] | INFO -> Using symlinks: False[0m
[2024-09-13 18:13] [36;20m[comfyui_controlnet_aux] | INFO -> Using ort providers: ['CUDAExecutionProvider', 'DirectMLExecutionProvider', 'OpenVINOExecutionProvider', 'ROCMExecutionProvider', 'CPUExecutionProvider', 'CoreMLExecutionProvider'][0m
[2024-09-13 18:13] DWPose: Onnxruntime with acceleration providers detected
[2024-09-13 18:13] [1;35m### [START] ComfyUI AlekPet Nodes [1;34mv1.0.28[0m[1;35m ###[0m
[2024-09-13 18:13] [92mNode -> ArgosTranslateNode: [93mArgosTranslateCLIPTextEncodeNode, ArgosTranslateTextNode[0m [92m[Loading] [0m
[2024-09-13 18:13] [92mNode -> DeepTranslatorNode: [93mDeepTranslatorCLIPTextEncodeNode, DeepTranslatorTextNode[0m [92m[Loading] [0m
[2024-09-13 18:13] [92mNode -> GoogleTranslateNode: [93mGoogleTranslateCLIPTextEncodeNode, GoogleTranslateTextNode[0m [92m[Loading] [0m
[2024-09-13 18:13] [92mNode -> PoseNode: [93mPoseNode[0m [92m[Loading] [0m
[2024-09-13 18:13] [92mNode -> ExtrasNode: [93mPreviewTextNode, HexToHueNode, ColorsCorrectNode[0m [92m[Loading] [0m
[2024-09-13 18:13] [92mNode -> IDENode: [93mIDENode[0m [92m[Loading] [0m
[2024-09-13 18:13] [92mNode -> PainterNode: [93mPainterNode[0m [92m[Loading] [0m
[2024-09-13 18:13] [1;35m### [END] ComfyUI AlekPet Nodes ###[0m
[2024-09-13 18:13] Traceback (most recent call last):
  File "D:\comfyui\nodes.py", line 1993, in load_custom_node
    module_spec.loader.exec_module(module)
  File "<frozen importlib._bootstrap_external>", line 936, in exec_module
  File "<frozen importlib._bootstrap_external>", line 1073, in get_code
  File "<frozen importlib._bootstrap_external>", line 1130, in get_data
FileNotFoundError: [Errno 2] No such file or directory: 'D:\\comfyui\\custom_nodes\\ComfyUI_essentials\\__init__.py'

[2024-09-13 18:13] Cannot import D:\comfyui\custom_nodes\ComfyUI_essentials module for custom nodes: [Errno 2] No such file or directory: 'D:\\comfyui\\custom_nodes\\ComfyUI_essentials\\__init__.py'
[2024-09-13 18:13] Traceback (most recent call last):
  File "D:\comfyui\nodes.py", line 1993, in load_custom_node
    module_spec.loader.exec_module(module)
  File "<frozen importlib._bootstrap_external>", line 936, in exec_module
  File "<frozen importlib._bootstrap_external>", line 1073, in get_code
  File "<frozen importlib._bootstrap_external>", line 1130, in get_data
FileNotFoundError: [Errno 2] No such file or directory: 'D:\\comfyui\\custom_nodes\\image-resize-comfyui\\__init__.py'

[2024-09-13 18:13] Cannot import D:\comfyui\custom_nodes\image-resize-comfyui module for custom nodes: [Errno 2] No such file or directory: 'D:\\comfyui\\custom_nodes\\image-resize-comfyui\\__init__.py'
[2024-09-13 18:13] 
[2024-09-13 18:13] [92m[rgthree] Loaded 39 extraordinary nodes.[0m
[2024-09-13 18:13] [33m[rgthree] NOTE: Will NOT use rgthree's optimized recursive execution as ComfyUI has changed.[0m
[2024-09-13 18:13] 
[2024-09-13 18:13] 
Import times for custom nodes:
[2024-09-13 18:13]    0.0 seconds: D:\comfyui\custom_nodes\websocket_image_save.py
[2024-09-13 18:13]    0.0 seconds: D:\comfyui\custom_nodes\AIGODLIKE-COMFYUI-TRANSLATION
[2024-09-13 18:13]    0.0 seconds: D:\comfyui\custom_nodes\sdxl_prompt_styler
[2024-09-13 18:13]    0.0 seconds: D:\comfyui\custom_nodes\ComfyUI_cspnodes
[2024-09-13 18:13]    0.0 seconds (IMPORT FAILED): D:\comfyui\custom_nodes\image-resize-comfyui
[2024-09-13 18:13]    0.0 seconds (IMPORT FAILED): D:\comfyui\custom_nodes\ComfyUI_essentials
[2024-09-13 18:13]    0.0 seconds: D:\comfyui\custom_nodes\ComfyUI-Custom-Scripts
[2024-09-13 18:13]    0.0 seconds: D:\comfyui\custom_nodes\ComfyUI-MimicMotionWrapper-main
[2024-09-13 18:13]    0.0 seconds: D:\comfyui\custom_nodes\ComfyUI-MimicMotionWrapper
[2024-09-13 18:13]    0.0 seconds: D:\comfyui\custom_nodes\ComfyUI-Frame-Interpolation
[2024-09-13 18:13]    0.0 seconds: D:\comfyui\custom_nodes\rgthree-comfy
[2024-09-13 18:13]    0.0 seconds: D:\comfyui\custom_nodes\ComfyUI-AnimateDiff-Evolved
[2024-09-13 18:13]    0.0 seconds: D:\comfyui\custom_nodes\ComfyUI-KJNodes
[2024-09-13 18:13]    0.0 seconds: D:\comfyui\custom_nodes\comfyui_controlnet_aux
[2024-09-13 18:13]    0.0 seconds: D:\comfyui\custom_nodes\ComfyUI-Inspire-Pack
[2024-09-13 18:13]    0.1 seconds: D:\comfyui\custom_nodes\comfyui-workspace-manager
[2024-09-13 18:13]    0.2 seconds: D:\comfyui\custom_nodes\ComfyUI-VideoHelperSuite
[2024-09-13 18:13]    0.4 seconds: D:\comfyui\custom_nodes\ComfyUI-Manager
[2024-09-13 18:13]    0.9 seconds: D:\comfyui\custom_nodes\ComfyUI-Impact-Pack
[2024-09-13 18:13]    2.9 seconds: D:\comfyui\custom_nodes\ComfyUI_Custom_Nodes_AlekPet
[2024-09-13 18:13]   42.7 seconds (IMPORT FAILED): D:\comfyui\custom_nodes\ComfyUI-MimicMotion
[2024-09-13 18:13] 
[2024-09-13 18:13] Starting server

[2024-09-13 18:13] To see the GUI go to: http://127.0.0.1:8188
[2024-09-13 18:13] FETCH DATA from: D:\comfyui\custom_nodes\ComfyUI-Manager\extension-node-map.json [DONE]
[2024-09-13 18:13] [Inspire Pack] IPAdapterPlus is not installed.
[2024-09-13 18:30] got prompt
[2024-09-13 18:30] Failed to validate prompt for output 22:
[2024-09-13 18:30] * MimicMotionSampler 12:
[2024-09-13 18:30]   - Required input is missing: ref_image
[2024-09-13 18:30] Output will be ignored
[2024-09-13 18:30] !!! Exception during processing !!! ref_image and pose_images must have the same resolution
[2024-09-13 18:30] Traceback (most recent call last):
  File "D:\comfyui\execution.py", line 323, in execute
    output_data, output_ui, has_subgraph = get_output_data(obj, input_data_all, execution_block_cb=execution_block_cb, pre_execute_cb=pre_execute_cb)
                                           ^^^^^^^^^^^^^^^^^^^^^^^^^^^^^^^^^^^^^^^^^^^^^^^^^^^^^^^^^^^^^^^^^^^^^^^^^^^^^^^^^^^^^^^^^^^^^^^^^^^^^^^^^^
  File "D:\comfyui\execution.py", line 198, in get_output_data
    return_values = _map_node_over_list(obj, input_data_all, obj.FUNCTION, allow_interrupt=True, execution_block_cb=execution_block_cb, pre_execute_cb=pre_execute_cb)
                    ^^^^^^^^^^^^^^^^^^^^^^^^^^^^^^^^^^^^^^^^^^^^^^^^^^^^^^^^^^^^^^^^^^^^^^^^^^^^^^^^^^^^^^^^^^^^^^^^^^^^^^^^^^^^^^^^^^^^^^^^^^^^^^^^^^^^^^^^^^^^^^^^^^
  File "D:\comfyui\execution.py", line 169, in _map_node_over_list
    process_inputs(input_dict, i)
  File "D:\comfyui\execution.py", line 158, in process_inputs
    results.append(getattr(obj, func)(**inputs))
                   ^^^^^^^^^^^^^^^^^^^^^^^^^^^^
  File "D:\comfyui\custom_nodes\ComfyUI-MimicMotionWrapper-main\nodes.py", line 385, in process
    assert ref_image.shape[1:3] == pose_images.shape[1:3], "ref_image and pose_images must have the same resolution"
           ^^^^^^^^^^^^^^^^^^^^^^^^^^^^^^^^^^^^^^^^^^^^^^
AssertionError: ref_image and pose_images must have the same resolution

[2024-09-13 18:30] Prompt executed in 5.90 seconds
[2024-09-13 18:30] got prompt
[2024-09-13 18:30] Failed to validate prompt for output 22:
[2024-09-13 18:30] * MimicMotionSampler 12:
[2024-09-13 18:30]   - Required input is missing: pose_images
[2024-09-13 18:30] Output will be ignored
[2024-09-13 18:30] !!! Exception during processing !!! ref_image and pose_images must have the same resolution
[2024-09-13 18:30] Traceback (most recent call last):
  File "D:\comfyui\execution.py", line 323, in execute
    output_data, output_ui, has_subgraph = get_output_data(obj, input_data_all, execution_block_cb=execution_block_cb, pre_execute_cb=pre_execute_cb)
                                           ^^^^^^^^^^^^^^^^^^^^^^^^^^^^^^^^^^^^^^^^^^^^^^^^^^^^^^^^^^^^^^^^^^^^^^^^^^^^^^^^^^^^^^^^^^^^^^^^^^^^^^^^^^
  File "D:\comfyui\execution.py", line 198, in get_output_data
    return_values = _map_node_over_list(obj, input_data_all, obj.FUNCTION, allow_interrupt=True, execution_block_cb=execution_block_cb, pre_execute_cb=pre_execute_cb)
                    ^^^^^^^^^^^^^^^^^^^^^^^^^^^^^^^^^^^^^^^^^^^^^^^^^^^^^^^^^^^^^^^^^^^^^^^^^^^^^^^^^^^^^^^^^^^^^^^^^^^^^^^^^^^^^^^^^^^^^^^^^^^^^^^^^^^^^^^^^^^^^^^^^^
  File "D:\comfyui\execution.py", line 169, in _map_node_over_list
    process_inputs(input_dict, i)
  File "D:\comfyui\execution.py", line 158, in process_inputs
    results.append(getattr(obj, func)(**inputs))
                   ^^^^^^^^^^^^^^^^^^^^^^^^^^^^
  File "D:\comfyui\custom_nodes\ComfyUI-MimicMotionWrapper-main\nodes.py", line 385, in process
    assert ref_image.shape[1:3] == pose_images.shape[1:3], "ref_image and pose_images must have the same resolution"
           ^^^^^^^^^^^^^^^^^^^^^^^^^^^^^^^^^^^^^^^^^^^^^^
AssertionError: ref_image and pose_images must have the same resolution

[2024-09-13 18:30] Prompt executed in 0.02 seconds
[2024-09-13 18:30] got prompt
[2024-09-13 18:30] Failed to validate prompt for output 22:
[2024-09-13 18:30] * MimicMotionSampler 12:
[2024-09-13 18:30]   - Required input is missing: pose_images
[2024-09-13 18:30] Output will be ignored
[2024-09-13 18:30] !!! Exception during processing !!! ref_image and pose_images must have the same resolution
[2024-09-13 18:30] Traceback (most recent call last):
  File "D:\comfyui\execution.py", line 323, in execute
    output_data, output_ui, has_subgraph = get_output_data(obj, input_data_all, execution_block_cb=execution_block_cb, pre_execute_cb=pre_execute_cb)
                                           ^^^^^^^^^^^^^^^^^^^^^^^^^^^^^^^^^^^^^^^^^^^^^^^^^^^^^^^^^^^^^^^^^^^^^^^^^^^^^^^^^^^^^^^^^^^^^^^^^^^^^^^^^^
  File "D:\comfyui\execution.py", line 198, in get_output_data
    return_values = _map_node_over_list(obj, input_data_all, obj.FUNCTION, allow_interrupt=True, execution_block_cb=execution_block_cb, pre_execute_cb=pre_execute_cb)
                    ^^^^^^^^^^^^^^^^^^^^^^^^^^^^^^^^^^^^^^^^^^^^^^^^^^^^^^^^^^^^^^^^^^^^^^^^^^^^^^^^^^^^^^^^^^^^^^^^^^^^^^^^^^^^^^^^^^^^^^^^^^^^^^^^^^^^^^^^^^^^^^^^^^
  File "D:\comfyui\execution.py", line 169, in _map_node_over_list
    process_inputs(input_dict, i)
  File "D:\comfyui\execution.py", line 158, in process_inputs
    results.append(getattr(obj, func)(**inputs))
                   ^^^^^^^^^^^^^^^^^^^^^^^^^^^^
  File "D:\comfyui\custom_nodes\ComfyUI-MimicMotionWrapper-main\nodes.py", line 385, in process
    assert ref_image.shape[1:3] == pose_images.shape[1:3], "ref_image and pose_images must have the same resolution"
           ^^^^^^^^^^^^^^^^^^^^^^^^^^^^^^^^^^^^^^^^^^^^^^
AssertionError: ref_image and pose_images must have the same resolution

[2024-09-13 18:30] Prompt executed in 0.02 seconds
[2024-09-13 18:31] got prompt
[2024-09-13 18:31] Failed to validate prompt for output 22:
[2024-09-13 18:31] * MimicMotionSampler 12:
[2024-09-13 18:31]   - Required input is missing: ref_image
[2024-09-13 18:31] Output will be ignored
[2024-09-13 18:31] !!! Exception during processing !!! ref_image and pose_images must have the same resolution
[2024-09-13 18:31] Traceback (most recent call last):
  File "D:\comfyui\execution.py", line 323, in execute
    output_data, output_ui, has_subgraph = get_output_data(obj, input_data_all, execution_block_cb=execution_block_cb, pre_execute_cb=pre_execute_cb)
                                           ^^^^^^^^^^^^^^^^^^^^^^^^^^^^^^^^^^^^^^^^^^^^^^^^^^^^^^^^^^^^^^^^^^^^^^^^^^^^^^^^^^^^^^^^^^^^^^^^^^^^^^^^^^
  File "D:\comfyui\execution.py", line 198, in get_output_data
    return_values = _map_node_over_list(obj, input_data_all, obj.FUNCTION, allow_interrupt=True, execution_block_cb=execution_block_cb, pre_execute_cb=pre_execute_cb)
                    ^^^^^^^^^^^^^^^^^^^^^^^^^^^^^^^^^^^^^^^^^^^^^^^^^^^^^^^^^^^^^^^^^^^^^^^^^^^^^^^^^^^^^^^^^^^^^^^^^^^^^^^^^^^^^^^^^^^^^^^^^^^^^^^^^^^^^^^^^^^^^^^^^^
  File "D:\comfyui\execution.py", line 169, in _map_node_over_list
    process_inputs(input_dict, i)
  File "D:\comfyui\execution.py", line 158, in process_inputs
    results.append(getattr(obj, func)(**inputs))
                   ^^^^^^^^^^^^^^^^^^^^^^^^^^^^
  File "D:\comfyui\custom_nodes\ComfyUI-MimicMotionWrapper-main\nodes.py", line 385, in process
    assert ref_image.shape[1:3] == pose_images.shape[1:3], "ref_image and pose_images must have the same resolution"
           ^^^^^^^^^^^^^^^^^^^^^^^^^^^^^^^^^^^^^^^^^^^^^^
AssertionError: ref_image and pose_images must have the same resolution

[2024-09-13 18:31] Prompt executed in 0.02 seconds
[2024-09-13 18:31] got prompt
[2024-09-13 18:31] Failed to validate prompt for output 22:
[2024-09-13 18:31] * MimicMotionSampler 12:
[2024-09-13 18:31]   - Required input is missing: ref_image
[2024-09-13 18:31] Output will be ignored
[2024-09-13 18:31] !!! Exception during processing !!! ref_image and pose_images must have the same resolution
[2024-09-13 18:31] Traceback (most recent call last):
  File "D:\comfyui\execution.py", line 323, in execute
    output_data, output_ui, has_subgraph = get_output_data(obj, input_data_all, execution_block_cb=execution_block_cb, pre_execute_cb=pre_execute_cb)
                                           ^^^^^^^^^^^^^^^^^^^^^^^^^^^^^^^^^^^^^^^^^^^^^^^^^^^^^^^^^^^^^^^^^^^^^^^^^^^^^^^^^^^^^^^^^^^^^^^^^^^^^^^^^^
  File "D:\comfyui\execution.py", line 198, in get_output_data
    return_values = _map_node_over_list(obj, input_data_all, obj.FUNCTION, allow_interrupt=True, execution_block_cb=execution_block_cb, pre_execute_cb=pre_execute_cb)
                    ^^^^^^^^^^^^^^^^^^^^^^^^^^^^^^^^^^^^^^^^^^^^^^^^^^^^^^^^^^^^^^^^^^^^^^^^^^^^^^^^^^^^^^^^^^^^^^^^^^^^^^^^^^^^^^^^^^^^^^^^^^^^^^^^^^^^^^^^^^^^^^^^^^
  File "D:\comfyui\execution.py", line 169, in _map_node_over_list
    process_inputs(input_dict, i)
  File "D:\comfyui\execution.py", line 158, in process_inputs
    results.append(getattr(obj, func)(**inputs))
                   ^^^^^^^^^^^^^^^^^^^^^^^^^^^^
  File "D:\comfyui\custom_nodes\ComfyUI-MimicMotionWrapper-main\nodes.py", line 385, in process
    assert ref_image.shape[1:3] == pose_images.shape[1:3], "ref_image and pose_images must have the same resolution"
           ^^^^^^^^^^^^^^^^^^^^^^^^^^^^^^^^^^^^^^^^^^^^^^
AssertionError: ref_image and pose_images must have the same resolution

[2024-09-13 18:31] Prompt executed in 0.02 seconds
